Exception in Tkinter callback
Traceback (most recent call last):
  File "C:\Python34\lib\tkinter\__init__.py", line 1533, in __call__
    return self.func(*args)
  File "E:\python_project\navigator\navWindow.py", line 145, in runCommand
    output = dl645.sendCmd( dl645.toCOM( cmd_in['frame'] ) )
  File "E:\python_project\navigator\dl645.py", line 91, in sendCmd
    rs485 = serial.Serial(MeterPara['com'], MeterPara['baudrate'], parity=MeterPara['parity'], timeout=MeterPara['timeout'])
  File "C:\Python34\lib\site-packages\serial\serialwin32.py", line 38, in __init__
    SerialBase.__init__(self, *args, **kwargs)
  File "C:\Python34\lib\site-packages\serial\serialutil.py", line 282, in __init__
    self.open()
  File "C:\Python34\lib\site-packages\serial\serialwin32.py", line 66, in open
    raise SerialException("could not open port %r: %r" % (self.portstr, ctypes.WinError()))
serial.serialutil.SerialException: could not open port 'COM5': FileNotFoundError(2, '系统找不到指定的文件。', None, 2)
